Workbook

Sheet Monthly Close
A1: Acme Foods Co. -- Monthly Close Checklist
A2: January 2026
A4: # | B4: Close step | C4: Owner | D4: Status | E4: Notes
A5: 1 | B5: Broker commission accruals booked
A6: 2 | B6: Co-man payroll: approved hours x pay rates + 11% payroll tax load
A7: 3 | B7: Production labor & overhead reallocated by channel revenue %
A8: 4 | B8: Loan interest tie-out -- total booked ties to interest expense account
A9: 5 | B9: Prepaid amortization for the month
A10: 6 | B10: Trade spend / promo accruals
A11: 7 | B11: Unapplied cash, stale accruals & clearing accounts reviewed
A12: 8 | B12: TB review: out-of-balance = 0, no unmapped accounts
A13: 9 | B13: Packet generated -- layout matches prior month (board format)
A14: 10 | B14: Variance review & sign-off

Sheet Raw Input
A1: Account Number | B1: Account Name | C1: Debit | D1: Credit | E1: Channel
A2: 40000 | B2: Product Sales -- Wholesale | C2: 0 | D2: 520000 | E2: Wholesale
A3: 40100 | B3: Product Sales -- DTC | C3: 0 | D3: 210000 | E3: DTC
A4: 40200 | B4: Product Sales -- Foodservice | C4: 0 | D4: 95000 | E4: Foodservice
A5: 40300 | B5: Shipping Income | C5: 0 | D5: 18000 | E5: DTC
A6: 40400 | B6: Other Revenue | C6: 0 | D6: 6500
A7: 50000 | B7: Raw Materials | C7: 310000 | D7: 0 | E7: Wholesale
A8: 50100 | B8: Co-Man Production Fees | C8: 88000 | D8: 0 | E8: Wholesale
A9: 50200 | B9: Freight In | C9: 24500 | D9: 0 | E9: Foodservice
A10: 50300 | B10: Packaging | C10: 19000 | D10: 0 | E10: DTC
A11: 60000 | B11: Salaries & Wages | C11: 145000 | D11: 0 | E11: Overhead
A12: 60100 | B12: Payroll Taxes | C12: 15950 | D12: 0 | E12: Overhead
A13: 60200 | B13: Employee Benefits | C13: 12400 | D13: 0 | E13: Overhead
A14: 61000 | B14: Rent | C14: 18000 | D14: 0 | E14: Overhead
A15: 61100 | B15: Utilities | C15: 4200 | D15: 0 | E15: Overhead
A16: 62000 | B16: Accounting & Legal | C16: 9500 | D16: 0 | E16: Overhead
A17: 62100 | B17: Consulting | C17: 6000 | D17: 0 | E17: Overhead
A18: 63000 | B18: Advertising & Marketing | C18: 22000 | D18: 0 | E18: DTC
... A26: 66300 | B26: Bank Charges | C26: 950 | D26: 0 | E26: Overhead
A27: 66400 | B27: Miscellaneous | C27: 1750 | D27: 0
A28: 70000 | B28: Interest Income | C28: 0 | D28: 1200
A29: 70100 | B29: Gain on Sale of Assets | C29: 0 | D29: 2500
A30: 71000 | B30: Other Expense | C30: 4900 | D30: 0
A31: 10000 | B31: Cash -- Operating | C31: 142300 | D31: 0
A32: 10100 | B32: Cash -- Payroll | C32: 25000 | D32: 0
A33: 11000 | B33: Accounts Receivable | C33: 186400 | D33: 0
A34: 12000 | B34: Inventory -- Raw Materials | C34: 58000 | D34: 0
A35: 12100 | B35: Inventory -- Finished Goods | C35: 74500 | D35: 0
A36: 13000 | B36: Prepaid Insurance | C36: 14400 | D36: 0
A37: 13100 | B37: Prepaid Rent | C37: 9000 | D37: 0
A38: 14000 | B38: Other Current Assets | C38: 6200 | D38: 0
... A52: 31000 | B52: Retained Earnings | C52: 0 | D52: 123700

Sheet Adjustments
A1: Acme Foods Co. -- Grading Scale & Targets
A2: January 2026 -- edit the yellow cells; Dashboard grades update automatically
A3: KPI | B3: Target | C3: B band | D3: C band | E3: D band | F3: Direction
A4: Net Profit Margin | B4: 0.15 | C4: 0.02 | D4: 0.05 | E4: 0.08 | F4: higher
A5: Gross Margin | B5: 0.45 | C5: 0.03 | D5: 0.06 | E5: 0.1 | F5: higher
A6: Operating Margin | B6: 0.15 | C6: 0.02 | D6: 0.05 | E6: 0.08 | F6: higher
A7: Operating Expense Ratio | B7: 0.3 | C7: 0.02 | D7: 0.05 | E7: 0.08 | F7: lower
A8: Current Ratio | B8: 2 | C8: 0.25 | D8: 0.5 | E8: 0.75 | F8: higher
A9: Debt to Equity | B9: 1 | C9: 0.25 | D9: 0.5 | E9: 0.75 | F9: lower
A10: Interest Coverage | B10: 5 | C10: 1 | D10: 2 | E10: 3 | F10: higher
A11: Cash Runway | B11: 6 | C11: 1 | D11: 2 | E11: 3 | F11: higher
A12: Days Sales Outstanding | B12: 45 | C12: 5 | D12: 10 | E12: 15 | F12: lower
A13: Cash Conversion Cycle | B13: 30 | C13: 10 | D13: 20 | E13: 30 | F13: lower
A14: Quick Ratio | B14: 1 | C14: 0.2 | D14: 0.4 | E14: 0.6 | F14: higher
A17: How the grading scale works - Target: the goal for each KPI (edit freely). - B/C/D bands: how far below target (or above, for "lower" metrics) still earns that grade. Anything worse than the D band is an F. - Direction "higher" means bigger is better (margins, current ratio); "lower" means smaller is better (expense ratio, leverage). - Bands are in percentage points for margins, ratio points for ratios, months for cash runway, and days for the days-based metrics (days sales outstanding, cash conversion cycle).

Sheet Dashboard
A1: Acme Foods Co. -- KPI Dashboard
A2: January 2026
A3: HEADLINE RESULTS
A4: Revenue | B4: ='P&L'!B6 | C4: vs December 2025 | D4: 0.080788804 | E4: Top line for the period
A5: Net Income | B5: ='P&L'!B22 | C5: vs 2026 Budget | D5: 0.095609156 | E5: Budgeted $112,996
A6: Cash & Equivalents | B6: ='Balance Sheet'!B6 | C6: vs December 2025 | D6: 0.11533333 | E6: Balance Sheet cash position
A8: KPI | B8: Actual | C8: Target | D8: Grade | E8: Note
A9: Net Profit Margin | B9: ='P&L'!C23 | C9: =Adjustments!B4 | D9: =IF(B9>=Adjustments!$B$4,"A",IF(B9>=Adjustments!$B$4-Adjustments!$C$4,"B",IF(B9>=Adjustments!$B$4-Adjustments!$D$4,"C",IF(B9>=Adjustments!$B$4-Adjustments!$E$4,"D","F")))) | E9: Board target -- the headline number
A10: Gross Margin | B10: ='P&L'!C8 | C10: =Adjustments!B5 | D10: =IF(B10>=Adjustments!$B$5,"A",IF(B10>=Adjustments!$B$5-Adjustments!$C$5,"B",IF(B10>=Adjustments!$B$5-Adjustments!$D$5,"C",IF(B10>=Adjustments!$B$5-Adjustments!$E$5,"D","F")))) | E10: Pricing power & production efficiency
A11: Operating Margin | B11: ='P&L'!C19 | C11: =Adjustments!B6 | D11: =IF(B11>=Adjustments!$B$6,"A",IF(B11>=Adjustments!$B$6-Adjustments!$C$6,"B",IF(B11>=Adjustments!$B$6-Adjustments!$D$6,"C",IF(B11>=Adjustments!$B$6-Adjustments!$E$6,"D","F")))) | E11: Core operating performance
A12: Operating Expense Ratio | B12: ='P&L'!B18/'P&L'!B6 | C12: =Adjustments!B7 | D12: =IF(B12<=Adjustments!$B$7,"A",IF(B12<=Adjustments!$B$7+Adjustments!$C$7,"B",IF(B12<=Adjustments!$B$7+Adjustments!$D$7,"C",IF(B12<=Adjustments!$B$7+Adjustments!$E$7,"D","F")))) | E12: Overhead discipline (lower is better)
A13: Current Ratio | B13: ='Balance Sheet'!B11/'Balance Sheet'!B21 | C13: =Adjustments!B8 | D13: =IF(B13>=Adjustments!$B$8,"A",IF(B13>=Adjustments!$B$8-Adjustments!$C$8,"B",IF(B13>=Adjustments!$B$8-Adjustments!$D$8,"C",IF(B13>=Adjustments!$B$8-Adjustments!$E$8,"D","F")))) | E13: Short-term liquidity cushion
A14: Debt to Equity | B14: ='Balance Sheet'!B24/'Balance Sheet'!B29 | C14: =Adjustments!B9 | D14: =IF(B14<=Adjustments!$B$9,"A",IF(B14<=Adjustments!$B$9+Adjustments!$C$9,"B",IF(B14<=Adjustments!$B$9+Adjustments!$D$9,"C",IF(B14<=Adjustments!$B$9+Adjustments!$E$9,"D","F")))) | E14: Leverage (lower is better)
A15: Interest Coverage | B15: =IF('P&L'!B16=0,"N/A",('P&L'!B19+'P&L'!B16)/'P&L'!B16) | C15: =Adjustments!B10 | D15: =IF(B15>=Adjustments!$B$10,"A",IF(B15>=Adjustments!$B$10-Adjustments!$C$10,"B",IF(B15>=Adjustments!$B$10-Adjustments!$D$10,"C",IF(B15>=Adjustments!$B$10-Adjustments!$E$10,"D","F")))) | E15: Debt-service cushion (higher is better)
A16: Cash Runway | B16: =IF('P&L'!B18=0,"N/A",'Balance Sheet'!B6/('P&L'!B18/12)) | C16: =Adjustments!B11 | D16: =IF(B16>=Adjustments!$B$11,"A",IF(B16>=Adjustments!$B$11-Adjustments!$C$11,"B",IF(B16>=Adjustments!$B$11-Adjustments!$D$11,"C",IF(B16>=Adjustments!$B$11-Adjustments!$E$11,"D","F")))) | E16: Months of opex covered by cash (higher is better)
A17: Days Sales Outstanding | B17: =IF('P&L'!B6=0,"N/A",'Balance Sheet'!B7/('P&L'!B6*12/365)) | C17: =Adjustments!B12 | D17: =IF(B17<=Adjustments!$B$12,"A",IF(B17<=Adjustments!$B$12+Adjustments!$C$12,"B",IF(B17<=Adjustments!$B$12+Adjustments!$D$12,"C",IF(B17<=Adjustments!$B$12+Adjustments!$E$12,"D","F")))) | E17: Collection speed (lower is better)
A18: Cash Conversion Cycle | B18: =IF(OR('P&L'!B6=0,'P&L'!B7=0),"N/A",'Balance Sheet'!B7/('P&L'!B6*12/365)+'Balance Sheet'!B8/('P&L'!B7*12/365)-'Balance Sheet'!B16/('P&L'!B7*12/365)) | C18: =Adjustments!B13 | D18: =IF(B18<=Adjustments!$B$13,"A",IF(B18<=Adjustments!$B$13+Adjustments!$C$13,"B",IF(B18<=Adjustments!$B$13+Adjustments!$D$13,"C",IF(B18<=Adjustments!$B$13+Adjustments!$E$13,"D","F")))) | E18: Days cash is tied up in working capital (lower is better)
A19: Quick Ratio | B19: =IF('Balance Sheet'!B21=0,"N/A",('Balance Sheet'!B6+'Balance Sheet'!B7)/'Balance Sheet'!B21) | C19: =Adjustments!B14 | D19: =IF(B19>=Adjustments!$B$14,"A",IF(B19>=Adjustments!$B$14-Adjustments!$C$14,"B",IF(B19>=Adjustments!$B$14-Adjustments!$D$14,"C",IF(B19>=Adjustments!$B$14-Adjustments!$E$14,"D","F")))) | E19: Immediate liquidity without selling inventory (higher is better)

Sheet Analysis
A1: Acme Foods Co. -- Automatic Analysis
A2: January 2026 vs December 2025
A4: Variance by GL line
A5: GL line | B5: Current | C5: December 2025 | D5: $ Change | E5: % Change
A6: Revenue | B6: 849500 | C6: 786000 | D6: 63500 | E6: 0.080788804
A7: Cost of Goods Sold | B7: 441500 | C7: 415000 | D7: 26500 | E7: 0.063855422
A8: Cash & Cash Equivalents | B8: 167300 | C8: 150000 | D8: 17300 | E8: 0.11533333
A9: Accounts Receivable | B9: 186400 | C9: 172000 | D9: 14400 | E9: 0.08372093
A10: Long-Term Debt | B10: 185000 | C10: 195000 | D10: -10000 | E10: -0.051282051
A11: Inventory | B11: 132500 | C11: 123000 | D11: 9500 | E11: 0.077235772
A12: Property & Equipment, net | B12: 158700 | C12: 166500 | D12: -7800 | E12: -0.046846847
A13: Retained Earnings, Beginning | B13: 123700 | C13: 116020 | D13: 7680 | E13: 0.066195484
A14: Accounts Payable | B14: 98700 | C14: 91200 | D14: 7500 | E14: 0.082236842
A15: Salaries & Wages | B15: 145000 | C15: 139000 | D15: 6000 | E15: 0.043165468
A16: Sales & Marketing | B16: 36500 | C16: 34100 | D16: 2400 | E16: 0.070381232
A17: Accrued Expenses | B17: 34300 | C17: 32600 | D17: 1700 | E17: 0.052147239
... A32: Other Noncurrent Liabilities | B32: 9600 | C32: 9600 | D32: 0 | E32: 0
A34: Budget vs Actual (2026 Budget)
A35: GL line | B35: Actual | C35: Budget | D35: Variance $ | E35: Variance %
A36: Revenue | B36: 849500 | C36: 819767.5 | D36: 29732.5 | E36: 0.03626943
A37: Cost of Goods Sold | B37: 441500 | C37: 428255 | D37: 13245 | E37: 0.030927835
A38: Cash & Cash Equivalents | B38: 167300 | C38: 158935 | D38: 8365 | E38: 0.052631579
A39: Accounts Receivable | B39: 186400 | C39: 180808 | D39: 5592 | E39: 0.030927835
A40: Inventory | B40: 132500 | C40: 127200 | D40: 5300 | E40: 0.041666667
A41: Accounts Payable | B41: 98700 | C41: 94752 | D41: 3948 | E41: 0.041666667
A42: Long-Term Debt | B42: 185000 | C42: 188700 | D42: -3700 | E42: -0.019607843
A43: Retained Earnings, Beginning | B43: 123700 | C43: 120312.5 | D43: 3387.5 | E43: 0.028155844
A44: Salaries & Wages | B44: 145000 | C44: 142100 | D44: 2900 | E44: 0.020408163
A45: Property & Equipment, net | B45: 158700 | C45: 161589 | D45: -2889 | E45: -0.017878692
A46: Accrued Expenses | B46: 34300 | C46: 33271 | D46: 1029 | E46: 0.030927835
A47: Deferred Revenue | B47: 18000 | C47: 17100 | D47: 900 | E47: 0.052631579
... A62: Prepaid Expenses | B62: 23400 | C62: 23400 | D62: 0 | E62: 0
A64: Key findings
A65: • Revenue of $849,500 was up 8.1% vs December 2025; net income of $123,800 was up 27.0%, a 14.6% net margin (+2.2pp vs December 2025).
A66: • Largest movers: Cash & Cash Equivalents up 11.5% ($17,300).
A67: • Gross margin expanded to 48.0% (+0.8pp) -- COGS grew slower than revenue.
A68: • Liquidity is comfortable (current ratio 2.65); leverage at 1.31x debt-to-equity.
A69: • Quick ratio is 1.82 -- cash and receivables cover current liabilities without selling inventory.
A70: • Collections running at 7 days sales outstanding (on target).
A71: • Cash conversion cycle is 9 days (7 to collect + 9 of inventory - 7 to pay suppliers).
...

Sheet P&L
A1: Acme Foods Co. -- Income Statement
A2: January 2026
A5: Line | B5: Amount | C5: % of Revenue
A6: Revenue | B6: 849500
A7: Cost of Goods Sold | B7: 441500
A8: Gross Profit | B8: =B6-B7 | C8: =IF(B6=0,0,B8/B6)
A10: Salaries & Wages | B10: 145000
A11: Payroll Taxes & Benefits | B11: 28350
A12: Rent & Facilities | B12: 22200
A13: Professional Fees | B13: 15500
A14: Sales & Marketing | B14: 36500
A15: Depreciation & Amortization | B15: 11000
A16: Interest Expense | B16: 11250
A17: Other Operating Expenses | B17: 13200
A18: Total Operating Expenses | B18: =SUM(B10:B17)
A19: Operating Income | B19: =B8-B18 | C19: =IF(B6=0,0,B19/B6)
A21: Other Income (Expense), net | B21: -1200
A22: Net Income | B22: =B19+B21
A23: Net Profit Margin | C23: =IF(B6=0,0,B22/B6)

Sheet Detailed P&L
A1: Acme Foods Co. -- Detailed P&L
A2: January 2026
A3: Acct # | B3: Account | C3: Amount | D3: Channel
B4: Revenue
A5: 40000 | B5: Product Sales -- Wholesale | C5: 520000 | D5: Wholesale
A6: 40100 | B6: Product Sales -- DTC | C6: 210000 | D6: DTC
A7: 40200 | B7: Product Sales -- Foodservice | C7: 95000 | D7: Foodservice
A8: 40300 | B8: Shipping Income | C8: 18000 | D8: DTC
A9: 40400 | B9: Other Revenue | C9: 6500
B10: Total -- Revenue | C10: =SUM(C5:C9)
B12: Cost of Goods Sold
A13: 50000 | B13: Raw Materials | C13: 310000 | D13: Wholesale
A14: 50100 | B14: Co-Man Production Fees | C14: 88000 | D14: Wholesale
A15: 50200 | B15: Freight In | C15: 24500 | D15: Foodservice
A16: 50300 | B16: Packaging | C16: 19000 | D16: DTC
B17: Total -- Cost of Goods Sold | C17: =SUM(C13:C16)
B19: Salaries & Wages
A20: 60000 | B20: Salaries & Wages | C20: 145000 | D20: Overhead
B21: Total -- Salaries & Wages | C21: =SUM(C20:C20)
B23: Payroll Taxes & Benefits
A24: 60100 | B24: Payroll Taxes | C24: 15950 | D24: Overhead
A25: 60200 | B25: Employee Benefits | C25: 12400 | D25: Overhead
B26: Total -- Payroll Taxes & Benefits | C26: =SUM(C24:C25)
B28: Rent & Facilities
A29: 61000 | B29: Rent | C29: 18000 | D29: Overhead
A30: 61100 | B30: Utilities | C30: 4200 | D30: Overhead
B31: Total -- Rent & Facilities | C31: =SUM(C29:C30)
B33: Professional Fees
A34: 62000 | B34: Accounting & Legal | C34: 9500 | D34: Overhead
A35: 62100 | B35: Consulting | C35: 6000 | D35: Overhead
B36: Total -- Professional Fees | C36: =SUM(C34:C35)
B38: Sales & Marketing
A39: 63000 | B39: Advertising & Marketing | C39: 22000 | D39: DTC
A40: 63100 | B40: Trade Spend | C40: 14500 | D40: Wholesale
B41: Total -- Sales & Marketing | C41: =SUM(C39:C40)
B43: Depreciation & Amortization
A44: 64000 | B44: Depreciation Expense | C44: 7800 | D44: Overhead
A45: 64100 | B45: Amortization Expense | C45: 3200 | D45: Overhead
B46: Total -- Depreciation & Amortization | C46: =SUM(C44:C45)
B48: Interest Expense
...

Sheet Balance Sheet
A1: Acme Foods Co. -- Balance Sheet
A2: January 2026
A4: ASSETS
A5: Line | B5: Current Period | C5: Prior Period
A6: Cash & Cash Equivalents | B6: 167300 | C6: 150000
A7: Accounts Receivable | B7: 186400 | C7: 172000
A8: Inventory | B8: 132500 | C8: 123000
A9: Prepaid Expenses | B9: 23400 | C9: 22000
A10: Other Current Assets | B10: 6200 | C10: 6000
A11: Total Current Assets | B11: =SUM(B6:B10) | C11: =SUM(C6:C10)
A12: Property & Equipment, net | B12: 158700 | C12: 166500
A13: Other Noncurrent Assets | B13: 12000 | C13: 12000
A14: TOTAL ASSETS | B14: =B11+B12+B13 | C14: =C11+C12+C13
A15: LIABILITIES
A16: Accounts Payable | B16: 98700 | C16: 91200
A17: Accrued Expenses | B17: 34300 | C17: 32600
A18: Deferred Revenue | B18: 18000 | C18: 16500
A19: Current Portion of Long-Term Debt | B19: 36000 | C19: 36000
A20: Other Current Liabilities | B20: 7400 | C20: 7100
A21: Total Current Liabilities | B21: =SUM(B16:B20) | C21: =SUM(C16:C20)
A22: Long-Term Debt | B22: 185000 | C22: 195000
A23: Other Noncurrent Liabilities | B23: 9600 | C23: 9600
A24: TOTAL LIABILITIES | B24: =B21+B22+B23 | C24: =C21+C22+C23
A25: EQUITY
A26: Common Stock | B26: 50000 | C26: 50000
A27: Retained Earnings, Beginning | B27: 123700 | C27: 116020
A28: Net Income (from P&L) | B28: ='P&L'!B22 | C28: N/A
A29: TOTAL EQUITY | B29: =SUM(B26:B28)
A30: TOTAL LIABILITIES & EQUITY | B30: =B24+B29
A31: Balance Check (should be 0) | B31: =B14-B30

Sheet SCF
A1: Acme Foods Co. -- Statement of Cash Flows (Indirect Method)
A2: January 2026
A4: Line | B4: Amount
A5: Cash flows from operating activities
A6: Net income | B6: ='P&L'!B22
A7: Depreciation & amortization | B7: ='P&L'!B15
A8: (Increase) decrease in accounts receivable | B8: =IF('Balance Sheet'!C7="N/A","N/A",-('Balance Sheet'!B7-'Balance Sheet'!C7))
A9: (Increase) decrease in inventory | B9: =IF('Balance Sheet'!C8="N/A","N/A",-('Balance Sheet'!B8-'Balance Sheet'!C8))
A10: (Increase) decrease in prepaid expenses | B10: =IF('Balance Sheet'!C9="N/A","N/A",-('Balance Sheet'!B9-'Balance Sheet'!C9))
A11: (Increase) decrease in other current assets | B11: =IF('Balance Sheet'!C10="N/A","N/A",-('Balance Sheet'!B10-'Balance Sheet'!C10))
A12: Increase (decrease) in accounts payable | B12: =IF('Balance Sheet'!C16="N/A","N/A",('Balance Sheet'!B16-'Balance Sheet'!C16))
A13: Increase (decrease) in accrued expenses | B13: =IF('Balance Sheet'!C17="N/A","N/A",('Balance Sheet'!B17-'Balance Sheet'!C17))
A14: Increase (decrease) in deferred revenue | B14: =IF('Balance Sheet'!C18="N/A","N/A",('Balance Sheet'!B18-'Balance Sheet'!C18))
A15: Increase (decrease) in other current liabilities | B15: =IF('Balance Sheet'!C20="N/A","N/A",('Balance Sheet'!B20-'Balance Sheet'!C20))
A16: Net cash provided by operating activities | B16: =SUM(B6:B15)
A18: Cash flows from investing activities
A19: Purchases of property & equipment | B19: =-(('Balance Sheet'!B12-'Balance Sheet'!C12)+'P&L'!B15)
A20: Net cash used in investing activities | B20: =SUM(B19:B19)
A22: Cash flows from financing activities
A23: Proceeds (repayments) of debt, net | B23: =('Balance Sheet'!B19-'Balance Sheet'!C19)+('Balance Sheet'!B22-'Balance Sheet'!C22)
A24: Net cash provided by financing activities | B24: =SUM(B23:B23)
A26: Net change in cash | B26: =B16+B20+B24
A27: Cash, beginning of period | B27: ='Balance Sheet'!C6
A28: Cash, end of period | B28: ='Balance Sheet'!B6
A29: Check: ending = beginning + change (should be 0) | B29: =B28-(B27+B26)

Sheet Checks
A1: Acme Foods Co. -- Data Quality Checks
A2: January 2026
A3: Check | B3: Result | C3: Status | D3: Notes
A4: Import detection | B4: trial_balance (signed mode) | C4: "PASS" | D4: Detected debit/credit columns ('Debit'/'Credit'); treated as a trial balance.
A5: Trial balance out-of-balance (debits - credits) | B5: =SUM('Raw Input'!C2:C10000)-SUM('Raw Input'!D2:D10000) | C5: =IF(ABS(B5)<0.01,"PASS","FLAG") | D5: Debits must equal credits before the packet means anything.
A6: Unmapped accounts (no GL line) | B6: 0 | C6: =IF(B6=0,"PASS","FLAG") | D6: All accounts mapped.
A7: Accounts mapped by fuzzy name match (review) | B7: 0 | C7: =IF(B7=0,"PASS","REVIEW") | D7: Every account hit the mapping file exactly.
A8: P&L accounts missing channel/class | B8: 5 | C8: =IF(B8=0,"PASS","REVIEW") | D8: 40400 Other Revenue; 66400 Miscellaneous; 70000 Interest Income; 70100 Gain on Sale of Assets; 71000 Other Expense
A9: Cash & cash equivalents balance | B9: 167300 | C9: =IF(B9>=0,"PASS","FLAG") | D9: Tie to the bank reconciliation; investigate negatives.
A10: Net income tie-out (P&L vs Balance Sheet) | B10: ='P&L'!B22-'Balance Sheet'!B28 | C10: =IF(ABS(B10)<0.01,"PASS","FLAG") | D10: Must be zero.
A11: Balance sheet balanced (Assets - L&E) | B11: ='Balance Sheet'!B31 | C11: =IF(ABS(B11)<0.01,"PASS","FLAG") | D11: Must be zero.
A12: Packet tabs populated | B12: 10/10 | C12: "PASS" | D12: All ten tabs generated with data.
